Workbook

Sheet Movindu
A1: Timestamp | B1: Material No: | C1: Description | D1: Unit Value | E1: Quantity | F1: Total Value | G1: Image | H1: Machine Name | I1: Criticality | J1: Usability
A2: 46163.585 | B2: SM.007.001714.07.AA | C2: =VLOOKUP(B2, 'Full List'!B:C, 2, FALSE) -> BEARING-(SR-000-13-0006) | D2: =VLOOKUP(B2, 'Full List'!B:F, 5, FALSE) -> 630 | E2: =VLOOKUP(B2, 'Full List'!B:G, 6, FALSE) -> 861.47 | F2: =VLOOKUP(B2, 'Full List'!B:H, 7, FALSE) -> 542726.1 | G2: https://drive.google.com/open?id=1AmLLNXhNfpiok6EBeMsJV2sicdidPsyC https://drive.google.com/open?id=1yrnpiH513_TyTH-MBJx_w28c38iJSG9N
A3: 46163.592 | B3: SM.007.001050.00.00 | C3: =VLOOKUP(B3, 'Full List'!B:C, 2, FALSE) -> BEARING NU 230 ECJ | D3: =VLOOKUP(B3, 'Full List'!B:F, 5, FALSE) -> 1 | E3: =VLOOKUP(B3, 'Full List'!B:G, 6, FALSE) -> 210000 | F3: =VLOOKUP(B3, 'Full List'!B:H, 7, FALSE) -> 210000 | G3: https://drive.google.com/open?id=1VRQSCCwxANm4VAYAZzPYlUwiOABKob6z https://drive.google.com/open?id=1rqsrYCVfgDKO6vJj86kzGFzeEWMOlEIq https://drive.google.com/open?id=1oqC58j4eNl--SoyRWBSl-BCGBmSUDNSY
A4: 46163.61 | B4: SE.007.000164.05.87 | C4: =VLOOKUP(B4, 'Full List'!B:C, 2, FALSE) -> CARD-SMC.085.04.913 | D4: =VLOOKUP(B4, 'Full List'!B:F, 5, FALSE) -> 1 | E4: =VLOOKUP(B4, 'Full List'!B:G, 6, FALSE) -> 410350.8 | F4: =VLOOKUP(B4, 'Full List'!B:H, 7, FALSE) -> 410350.8 | G4: https://drive.google.com/open?id=1Itn2hwkEljQ9rnbsSQKkqfWdIDqy4q-U https://drive.google.com/open?id=1dgavfYaV8NXJG0_mSDkv0-X2ZnfwrI0f https://drive.google.com/open?id=1cRwKhl12W5-WE5NAP-uq5X0lE4xdvWOT
A5: 46163.614 | B5: SE.007.000181.05.87 | C5: =VLOOKUP(B5, 'Full List'!B:C, 2, FALSE) -> CARD-SMC.085.05.903 | D5: =VLOOKUP(B5, 'Full List'!B:F, 5, FALSE) -> 3 | E5: =VLOOKUP(B5, 'Full List'!B:G, 6, FALSE) -> 81012.74 | F5: =VLOOKUP(B5, 'Full List'!B:H, 7, FALSE) -> 243038.22 | G5: https://drive.google.com/open?id=1Q8znGCZjby0GXNieHsQZa1rZLj6m7zZ2 https://drive.google.com/open?id=1FUlW4rrxlVYh-T4CNz2mUe7ft1rul0kQ
A6: 46163.615 | B6: SE.007.000184.05.87 | C6: =VLOOKUP(B6, 'Full List'!B:C, 2, FALSE) -> CARD-SMC.085.05.914 | D6: =VLOOKUP(B6, 'Full List'!B:F, 5, FALSE) -> 1 | E6: =VLOOKUP(B6, 'Full List'!B:G, 6, FALSE) -> 363427.23 | F6: =VLOOKUP(B6, 'Full List'!B:H, 7, FALSE) -> 363427.23 | G6: https://drive.google.com/open?id=1QpWs2dviMVwSBa-QdGPsCpR-INED8wum https://drive.google.com/open?id=1lch9utjjuK2zDScVoUgJFbQvz1HtHh0E
A7: 46163.616 | B7: SE.007.000193.03.78 | C7: =VLOOKUP(B7, 'Full List'!B:C, 2, FALSE) -> #N/A | D7: =VLOOKUP(B7, 'Full List'!B:F, 5, FALSE) -> #N/A | E7: =VLOOKUP(B7, 'Full List'!B:G, 6, FALSE) -> #N/A | F7: =VLOOKUP(B7, 'Full List'!B:H, 7, FALSE) -> #N/A | G7: https://drive.google.com/open?id=1GQNjWHTUhP8sQ9YXJ2Jv2gEdPlOf0_hL https://drive.google.com/open?id=1fEphtp8wAOwbIc2s13QGonUwHF-6kDq-
A8: 46163.617 | B8: SE.007.000199.03.78 | C8: =VLOOKUP(B8, 'Full List'!B:C, 2, FALSE) -> CARD-SMC.085.08.922 | D8: =VLOOKUP(B8, 'Full List'!B:F, 5, FALSE) -> 3 | E8: =VLOOKUP(B8, 'Full List'!B:G, 6, FALSE) -> 773263.52 | F8: =VLOOKUP(B8, 'Full List'!B:H, 7, FALSE) -> 2319790.6 | G8: https://drive.google.com/open?id=1p9zrdcmK0MkIiA7S9Km46yCG27IDL6ng https://drive.google.com/open?id=1_eC-iMGdOocnMfiUHiBofUUn28NmOlfE https://drive.google.com/open?id=1gjVtWallzbCeJUmcDSe2I4TZV02uARQe
A9: 46163.618 | B9: SE.007.000211.05.97 | C9: =VLOOKUP(B9, 'Full List'!B:C, 2, FALSE) -> CARD-SMC.085.10.975-SMC.085.15.934 | D9: =VLOOKUP(B9, 'Full List'!B:F, 5, FALSE) -> 3 | E9: =VLOOKUP(B9, 'Full List'!B:G, 6, FALSE) -> 905821.77 | F9: =VLOOKUP(B9, 'Full List'!B:H, 7, FALSE) -> 2717465.3 | G9: https://drive.google.com/open?id=1qZM2YxwYjQFfOMeaOwrBvIi7gGkkkeFo https://drive.google.com/open?id=1vWzWQa_cUEknqx6SoKbWgD6_MVW-K20a
A10: 46163.618 | B10: SE.007.000233.05.87 | C10: =VLOOKUP(B10, 'Full List'!B:C, 2, FALSE) -> CARD-SMC.085.17.920 | D10: =VLOOKUP(B10, 'Full List'!B:F, 5, FALSE) -> 2 | E10: =VLOOKUP(B10, 'Full List'!B:G, 6, FALSE) -> 667696.56 | F10: =VLOOKUP(B10, 'Full List'!B:H, 7, FALSE) -> 1335393.1 | G10: https://drive.google.com/open?id=17IGxrfYvwpdr7G1xvY07ZGVEKp2QfCiH https://drive.google.com/open?id=116IIVTnogseZ4RblTUdcDC5zkkkYOFBC
A11: 46163.691 | B11: SE.007.000238.03.78 | C11: =VLOOKUP(B11, 'Full List'!B:C, 2, FALSE) -> CARD-SMC.086.01.940 | D11: =VLOOKUP(B11, 'Full List'!B:F, 5, FALSE) -> 1 | E11: =VLOOKUP(B11, 'Full List'!B:G, 6, FALSE) -> 294594.69 | F11: =VLOOKUP(B11, 'Full List'!B:H, 7, FALSE) -> 294594.69 | G11: https://drive.google.com/open?id=1VQBeUB_UVegAzckj-INDBFCrKiDTsKq6 https://drive.google.com/open?id=1Zd0BfsZ0RlTfEdd6CmKn5mFPeJ4P3TDF
A12: 46163.691 | B12: SE.007.000232.05.87 | C12: =VLOOKUP(B12, 'Full List'!B:C, 2, FALSE) -> CARD-SMC.085.17.907 | D12: =VLOOKUP(B12, 'Full List'!B:F, 5, FALSE) -> 2 | E12: =VLOOKUP(B12, 'Full List'!B:G, 6, FALSE) -> 878669.27 | F12: =VLOOKUP(B12, 'Full List'!B:H, 7, FALSE) -> 1757338.5 | G12: https://drive.google.com/open?id=1WjFc4WLb6E2b1RzEl01IL3GDM_OUOXMV https://drive.google.com/open?id=1M9MXrcGscrsu5cLp_03L_KFUmn9J_X7u
A13: 46164.405 | B13: SE.007.000423.05.00 | C13: =VLOOKUP(B13, 'Full List'!B:C, 2, FALSE) -> CARD"OR" SMC08504950-P2 20.1.6 | D13: =VLOOKUP(B13, 'Full List'!B:F, 5, FALSE) -> 1 | E13: =VLOOKUP(B13, 'Full List'!B:G, 6, FALSE) -> 684723.55 | F13: =VLOOKUP(B13, 'Full List'!B:H, 7, FALSE) -> 684723.55 | G13: https://drive.google.com/open?id=1PS9yG_5MZowt-c2rPv1JTVP18sy4O-60 https://drive.google.com/open?id=1JeEpSZ2jWGQ8FVKSNdZirLAxUsHmJ188
... A72: 46167.474 | B72: SE.007.000458.06.9B | C72: =VLOOKUP(B72, 'Full List'!B:C, 2, FALSE) -> ELECTRONIC CARD HPC 3HV (PK-XAARHPC3) | D72: =VLOOKUP(B72, 'Full List'!B:F, 5, FALSE) -> 18 | E72: =VLOOKUP(B72, 'Full List'!B:G, 6, FALSE) -> 222287.26 | F72: =VLOOKUP(B72, 'Full List'!B:H, 7, FALSE) -> 4001170.7 | G72: https://drive.google.com/open?id=1A4VE8x6xj3uLpmGI4PMAr3ELae9o05cO https://drive.google.com/open?id=1j-YyKOQSNSijK5bgb9TYxQQyeXa5s4uA
B73: SM.007.000334.05.90 | C73: =VLOOKUP(B73, 'Full List'!B:C, 2, FALSE) -> COUPLING 1305530-143/34 | D73: =VLOOKUP(B73, 'Full List'!B:F, 5, FALSE) -> 22 | E73: =VLOOKUP(B73, 'Full List'!B:G, 6, FALSE) -> 29295.89 | F73: =VLOOKUP(B73, 'Full List'!B:H, 7, FALSE) -> 644509.58 | G73: https://drive.google.com/open?id=17iDKT8oiP99DJ3bcAcO7otwRd3RVRYzE https://drive.google.com/open?id=1kTn4TcNPdq3wah0c46yIiUY7xj1qa26y https://drive.google.com/open?id=1kPWGSRZ9d-OpU9uXZ8PYcXPxu7SX8nZ7
B74: SM.007.000533.00.00 | C74: =VLOOKUP(B74, 'Full List'!B:C, 2, FALSE) -> BEARING-6002 2ZC3 | D74: =VLOOKUP(B74, 'Full List'!B:F, 5, FALSE) -> 550 | E74: =VLOOKUP(B74, 'Full List'!B:G, 6, FALSE) -> 1154.22 | F74: =VLOOKUP(B74, 'Full List'!B:H, 7, FALSE) -> 634821 | G74: https://drive.google.com/open?id=165pvob3v0klkw1BfIxdU9oCePrGjYo9J https://drive.google.com/open?id=1l9AjirIxbP-6fxqBfngbRHkOxSP-OmpJ https://drive.google.com/open?id=1WrMzyCLCV_QTuGaPwaJmHNBqHVyq9VWk
B75: SM.007.000682.00.00 | C75: =VLOOKUP(B75, 'Full List'!B:C, 2, FALSE) -> BEARING 23220 EK/C3 | D75: =VLOOKUP(B75, 'Full List'!B:F, 5, FALSE) -> 2 | E75: =VLOOKUP(B75, 'Full List'!B:G, 6, FALSE) -> 137500 | F75: =VLOOKUP(B75, 'Full List'!B:H, 7, FALSE) -> 275000 | G75: https://drive.google.com/open?id=1YJtc2uMN1B4-Up9cU4LET2pnF1Af3lk3 https://drive.google.com/open?id=15g9lq23RkAMyWi7B-s2TjdTho5sNrq-f

Sheet Arushan
A1: Timestamp | B1: Material No: | C1: Description | D1: Unit Value | E1: Quantity | F1: Total Value | G1: Image | H1: Machine Name | I1: Criticality | J1: Usability
A2: 46162.726 | B2: SM.007.001049.00.00 | C2: =VLOOKUP(B2, 'Full List'!B:C, 2, FALSE) -> BEARING NU 316 ECJ | D2: =VLOOKUP(B2, 'Full List'!B:G, 6, FALSE) -> 54988 | E2: =VLOOKUP(B2, 'Full List'!B:F, 5, FALSE) -> 4 | F2: =VLOOKUP(B2, 'Full List'!B:H, 7, FALSE) -> 219952 | G2: https://drive.google.com/open?id=17Pb7Wcf1uAsvQdQLtMPsXPEpePDXKtKn https://drive.google.com/open?id=1s9U2lLNmzkGwRrpBTJmAmvi5NMX7iUt5 https://drive.google.com/open?id=1zve26BLu9UglFAmPGJgZS3UYhojRr-Qo
A3: 46162.734 | B3: SM.007.003098.00.00 | C3: =VLOOKUP(B3, 'Full List'!B:C, 2, FALSE) -> BEARING NTN 23060BKD1 | D3: =VLOOKUP(B3, 'Full List'!B:G, 6, FALSE) -> 421500 | E3: =VLOOKUP(B3, 'Full List'!B:F, 5, FALSE) -> 2 | F3: =VLOOKUP(B3, 'Full List'!B:H, 7, FALSE) -> 843000 | G3: https://drive.google.com/open?id=1cdn0jpC2WHUfjGK6IBw4h7pSc6ezRd2f https://drive.google.com/open?id=13WKVBgaz2d5SZdfDcuKWXG9NzgY2DzV1
A4: 46162.737 | B4: SM.007.000797.09.4Y | C4: =VLOOKUP(B4, 'Full List'!B:C, 2, FALSE) -> BEARING-(UCHA204) | D4: =VLOOKUP(B4, 'Full List'!B:G, 6, FALSE) -> 5190.67 | E4: =VLOOKUP(B4, 'Full List'!B:F, 5, FALSE) -> 34 | F4: =VLOOKUP(B4, 'Full List'!B:H, 7, FALSE) -> 176482.78 | G4: https://drive.google.com/open?id=1bDAYZjcTleXkP1mlZDtC2HY8tmp4i0oB https://drive.google.com/open?id=1IbPPDFf1TIevyIbf-cCbt22QEPrs0QOl
A5: 46162.739 | B5: SM.007.003107.00.00 | C5: =VLOOKUP(B5, 'Full List'!B:C, 2, FALSE) -> ONE WAY CLUTCH BEARING CSK30 (30x62x16 mm) | D5: =VLOOKUP(B5, 'Full List'!B:G, 6, FALSE) -> 18500 | E5: =VLOOKUP(B5, 'Full List'!B:F, 5, FALSE) -> 10 | F5: =VLOOKUP(B5, 'Full List'!B:H, 7, FALSE) -> 185000 | G5: https://drive.google.com/open?id=12D3c8YNVFERvETpNqaajn7wpmNdQg2sG
A6: 46162.762 | B6: SM.007.000737.00.00 | C6: =VLOOKUP(B6, 'Full List'!B:C, 2, FALSE) -> BEARING UCPA 205 | D6: =VLOOKUP(B6, 'Full List'!B:G, 6, FALSE) -> 7418.75 | E6: =VLOOKUP(B6, 'Full List'!B:F, 5, FALSE) -> 38 | F6: =VLOOKUP(B6, 'Full List'!B:H, 7, FALSE) -> 281912.5 | G6: https://drive.google.com/open?id=1GLH5xPr-BWXULiIJvYjDVRkgQBFnc256 https://drive.google.com/open?id=1Wn4hdKm7oHKCv4gSqM-U5yOlZczTP0_Y
A7: 46162.766 | B7: SM.015.004216.19.6P | C7: =VLOOKUP(B7, 'Full List'!B:C, 2, FALSE) -> TURBO CHARGER (317-6388) | D7: =VLOOKUP(B7, 'Full List'!B:G, 6, FALSE) -> 892812 | E7: =VLOOKUP(B7, 'Full List'!B:F, 5, FALSE) -> 1 | F7: =VLOOKUP(B7, 'Full List'!B:H, 7, FALSE) -> 892812 | G7: https://drive.google.com/open?id=1I_7rRhIVdLz7rfYAm5h3Zska6LMrQACq https://drive.google.com/open?id=1lCwVeY6GLZRCHklCSllMabgos1Oixe3s
A8: 46162.775 | B8: SM.015.004214.19.6P | C8: =VLOOKUP(B8, 'Full List'!B:C, 2, FALSE) -> LIFT CYLINDER SEAL KIT CAT914K (455-2277) | D8: =VLOOKUP(B8, 'Full List'!B:G, 6, FALSE) -> 238904.39 | E8: =VLOOKUP(B8, 'Full List'!B:F, 5, FALSE) -> 3 | F8: =VLOOKUP(B8, 'Full List'!B:H, 7, FALSE) -> 716713.17 | G8: https://drive.google.com/open?id=1JvnmWd8tzrxqndH50NijQuqiJ8Sc3ar_ https://drive.google.com/open?id=1Ky1cUA9uneI6ul7X_NtXUHDpYbTzZuNo
A9: 46162.778 | B9: SM.015.001835.19.6P | C9: =VLOOKUP(B9, 'Full List'!B:C, 2, FALSE) -> SPIDER GP-(8Y0809) | D9: =VLOOKUP(B9, 'Full List'!B:G, 6, FALSE) -> 95939 | E9: =VLOOKUP(B9, 'Full List'!B:F, 5, FALSE) -> 5 | F9: =VLOOKUP(B9, 'Full List'!B:H, 7, FALSE) -> 479695 | G9: https://drive.google.com/open?id=1DSSI0M2FRz36HUF5XLv27vZr1wCowEFG https://drive.google.com/open?id=1PGM_rBfC3kVzh1O0m3_AVjQ8q60T9WFh
A10: 46162.78 | B10: SM.015.001718.19.6P | C10: =VLOOKUP(B10, 'Full List'!B:C, 2, FALSE) -> SPIDER &amp; BEARING AS. 5V 1168 | D10: =VLOOKUP(B10, 'Full List'!B:G, 6, FALSE) -> 82362 | E10: =VLOOKUP(B10, 'Full List'!B:F, 5, FALSE) -> 4 | F10: =VLOOKUP(B10, 'Full List'!B:H, 7, FALSE) -> 329448 | G10: https://drive.google.com/open?id=129FRZXtZuB843Na9mqIrb7D22oN3lebG https://drive.google.com/open?id=1uQJLP32U9yMTq3RLMO5M2_P_BLN4aRp4
A11: 46162.799 | B11: SM.015.004714.19.6P | C11: =VLOOKUP(B11, 'Full List'!B:C, 2, FALSE) -> CONTROL AS-RACK-(7C1514 / 1707670) | D11: =VLOOKUP(B11, 'Full List'!B:G, 6, FALSE) -> 324300 | E11: =VLOOKUP(B11, 'Full List'!B:F, 5, FALSE) -> 1 | F11: =VLOOKUP(B11, 'Full List'!B:H, 7, FALSE) -> 324300 | G11: https://drive.google.com/open?id=1ntr8hxELHuV114pjYypsTviIW6aBnu3T https://drive.google.com/open?id=1yQK6zhYyTywVbPNZnl6Npj0sGvUxcXL-
A12: 46162.803 | B12: SM.015.004687.19.6P | C12: =VLOOKUP(B12, 'Full List'!B:C, 2, FALSE) -> ARM AS-LIFTER-(7W3989) | D12: =VLOOKUP(B12, 'Full List'!B:G, 6, FALSE) -> 40513.2 | E12: =VLOOKUP(B12, 'Full List'!B:F, 5, FALSE) -> 8 | F12: =VLOOKUP(B12, 'Full List'!B:H, 7, FALSE) -> 324105.6 | G12: https://drive.google.com/open?id=116yg7DsDIV4rgQ358TMqKEI48Xkz4_5D https://drive.google.com/open?id=1jb3NLL7tZNam1mZcXgw6eaGV0CWnJrnN
A13: 46162.858 | B13: SM.015.004738.19.6P | C13: =VLOOKUP(B13, 'Full List'!B:C, 2, FALSE) -> PISTON (9C8772) | D13: =VLOOKUP(B13, 'Full List'!B:G, 6, FALSE) -> 319890 | E13: =VLOOKUP(B13, 'Full List'!B:F, 5, FALSE) -> 1 | F13: =VLOOKUP(B13, 'Full List'!B:H, 7, FALSE) -> 319890 | G13: https://drive.google.com/open?id=1k74BERniqn0jEDHsROQVlJ5kTdaSVtJA https://drive.google.com/open?id=1Pxyz99wwCYCXffS9PH_J_A1TwBUNlWU2
... A26: 46163.27 | B26: SM.015.003786.19.6Q | C26: =VLOOKUP(B26, 'Full List'!B:C, 2, FALSE) -> MOUNT-(3EB-01-31640) | D26: =VLOOKUP(B26, 'Full List'!B:G, 6, FALSE) -> 27300 | E26: =VLOOKUP(B26, 'Full List'!B:F, 5, FALSE) -> 8 | F26: =VLOOKUP(B26, 'Full List'!B:H, 7, FALSE) -> 218400 | G26: https://drive.google.com/open?id=1JWtLaQtPGlGCIkKGfnyQKRodvB1nEOnN https://drive.google.com/open?id=1u1cEeDe9tUv8GxyoyMHoAvPGlNhrinWv https://drive.google.com/open?id=1GIYDgoit-fXg9vqpdZXw20vTi1b9cFVQ
A27: 46163.271 | C27: =VLOOKUP(B27, 'Full List'!B:C, 2, FALSE) -> #N/A | D27: =VLOOKUP(B27, 'Full List'!B:G, 6, FALSE) -> #N/A | E27: =VLOOKUP(B27, 'Full List'!B:F, 5, FALSE) -> #N/A | F27: =VLOOKUP(B27, 'Full List'!B:H, 7, FALSE) -> #N/A
A28: 46163.284 | B28: SM.002.000050.14.5R | C28: =VLOOKUP(B28, 'Full List'!B:C, 2, FALSE) -> ELEMENT-AIR CLEANER INNER-8N2556 | D28: =VLOOKUP(B28, 'Full List'!B:G, 6, FALSE) -> 137478.16 | E28: =VLOOKUP(B28, 'Full List'!B:F, 5, FALSE) -> 5 | F28: =VLOOKUP(B28, 'Full List'!B:H, 7, FALSE) -> 687390.8 | G28: https://drive.google.com/open?id=18yrlfTY84S3iL0TAzO_XbEP1SZSeM-yp https://drive.google.com/open?id=1hGsgUWkdOa5SoyDSed6jIoTXY_cRj4V5
A29: 46163.286 | B29: SM.010.002648.14.5P | C29: =VLOOKUP(B29, 'Full List'!B:C, 2, FALSE) -> VALVE OIL TEMPERATURE BYPASS (39902374) | D29: =VLOOKUP(B29, 'Full List'!B:G, 6, FALSE) -> 188400 | E29: =VLOOKUP(B29, 'Full List'!B:F, 5, FALSE) -> 1 | F29: =VLOOKUP(B29, 'Full List'!B:H, 7, FALSE) -> 188400 | G29: https://drive.google.com/open?id=18RfhYXNpHhS9cx766RcVZj3ZZF8sUeXS https://drive.google.com/open?id=1Oc_cz6KsjWBQoyzwxYrZZ0GnOHl_r-JR https://drive.google.com/open?id=1v-uMfa4AiFCE3mwF5hCoZwKSZhFrY3mL
A30: 46163.288 | B30: SM.010.002548.14.5P | C30: =VLOOKUP(B30, 'Full List'!B:C, 2, FALSE) -> VALVE, REGULATOR (100 &125 PSI) - (39905542) | D30: =VLOOKUP(B30, 'Full List'!B:G, 6, FALSE) -> 203686 | E30: =VLOOKUP(B30, 'Full List'!B:F, 5, FALSE) -> 2 | F30: =VLOOKUP(B30, 'Full List'!B:H, 7, FALSE) -> 407372 | G30: https://drive.google.com/open?id=1npQgBI8fwPHPdNjWNoj2nk0dJc7eEM6I https://drive.google.com/open?id=1Dnhx-JHEPNCYAKNCD4W6kncRKyphQP4P
A31: 46163.289 | B31: SM.010.000403.14.5P | C31: =VLOOKUP(B31, 'Full List'!B:C, 2, FALSE) -> Valve blowdown .50 NPT (39120472) | D31: =VLOOKUP(B31, 'Full List'!B:G, 6, FALSE) -> 92422.01 | E31: =VLOOKUP(B31, 'Full List'!B:F, 5, FALSE) -> 2 | F31: =VLOOKUP(B31, 'Full List'!B:H, 7, FALSE) -> 184844.02 | G31: https://drive.google.com/open?id=143e9cq2Q1woCploxvWzha4YfccLWE7_q https://drive.google.com/open?id=1cK13uccs4PlaocHIfdC3jArkfPU0Oxa1
A32: 46163.29 | B32: SM.010.002545.14.5P | C32: =VLOOKUP(B32, 'Full List'!B:C, 2, FALSE) -> VALVE SOLENOID 3-WAY - (39530852) | D32: =VLOOKUP(B32, 'Full List'!B:G, 6, FALSE) -> 61330 | E32: =VLOOKUP(B32, 'Full List'!B:F, 5, FALSE) -> 3 | F32: =VLOOKUP(B32, 'Full List'!B:H, 7, FALSE) -> 183990 | G32: https://drive.google.com/open?id=1HHotBz4L-I1UcQc2-2lhEyE40kGQeJ1f
A33: 46163.292 | B33: SM.010.000404.14.5P | C33: =VLOOKUP(B33, 'Full List'!B:C, 2, FALSE) -> Valve oil stop 1.3L SAE (39476569) | D33: =VLOOKUP(B33, 'Full List'!B:G, 6, FALSE) -> 285733.33 | E33: =VLOOKUP(B33, 'Full List'!B:F, 5, FALSE) -> 3 | F33: =VLOOKUP(B33, 'Full List'!B:H, 7, FALSE) -> 857199.99 | G33: https://drive.google.com/open?id=1uE1JpkvfzcPxLqJbYvwKUft8Z4Rl71s9 https://drive.google.com/open?id=1W7xIwVw_PgFyniO4GZt30P8lA8YBSbtK https://drive.google.com/open?id=15ypncd6LuEk9Rxx4wb5oFxDsH95l_Tfy
A34: 46163.293 | B34: SM.010.002649.14.5P | C34: =VLOOKUP(B34, 'Full List'!B:C, 2, FALSE) -> LINE FILTER ELEMENT (CCN 85565943) | D34: =VLOOKUP(B34, 'Full List'!B:G, 6, FALSE) -> 164300 | E34: =VLOOKUP(B34, 'Full List'!B:F, 5, FALSE) -> 4 | F34: =VLOOKUP(B34, 'Full List'!B:H, 7, FALSE) -> 657200 | G34: https://drive.google.com/open?id=1hHeO4MFC-YjpWnsH5keQwLsEtAH0uSOo https://drive.google.com/open?id=1Y5R88RZkEvVGVIhHuBEkkevO2cwkCXn4
A35: 46163.295 | B35: SM.002.000051.14.5R | C35: =VLOOKUP(B35, 'Full List'!B:C, 2, FALSE) -> ELEMENT-AIR CLEANER OUTER-8N6309 | D35: =VLOOKUP(B35, 'Full List'!B:G, 6, FALSE) -> 130500.25 | E35: =VLOOKUP(B35, 'Full List'!B:F, 5, FALSE) -> 2 | F35: =VLOOKUP(B35, 'Full List'!B:H, 7, FALSE) -> 261000.5 | G35: https://drive.google.com/open?id=1ThDGa3BT_jua6rpF0ch2T1w33Sn8MlVY https://drive.google.com/open?id=1v5Pox-k4hdYbjaWTBkhqTQiZeUmlZQtf
A36: 46163.296 | B36: SM.002.000129.14.5P | C36: =VLOOKUP(B36, 'Full List'!B:C, 2, FALSE) -> FILTER-COOLANT-39911631 | D36: =VLOOKUP(B36, 'Full List'!B:G, 6, FALSE) -> 46380.04 | E36: =VLOOKUP(B36, 'Full List'!B:F, 5, FALSE) -> 6 | F36: =VLOOKUP(B36, 'Full List'!B:H, 7, FALSE) -> 278280.24 | G36: https://drive.google.com/open?id=1Pt6kxqrq9kU4THtVGAMXqeK1KoPkKcDi https://drive.google.com/open?id=12Zko9VFC_pya5f3m-wJ7bUZbpQ4Ds_Jl\
A37: 46163.297 | B37: SM.010.002643.14.BA | C37: =VLOOKUP(B37, 'Full List'!B:C, 2, FALSE) -> HOSE (1625595500) | D37: =VLOOKUP(B37, 'Full List'!B:G, 6, FALSE) -> 528605.7 | E37: =VLOOKUP(B37, 'Full List'!B:F, 5, FALSE) -> 1 | F37: =VLOOKUP(B37, 'Full List'!B:H, 7, FALSE) -> 528605.7 | G37: https://drive.google.com/open?id=149Woe8csoiCAfWzdpIgJq8YF_sx1wA4K https://drive.google.com/open?id=1AzVMJl8AmUNuZUJzRKFnSQghFQxXX7sO
A38: 46163.299 | B38: SM.002.000353.14.BA | C38: =VLOOKUP(B38, 'Full List'!B:C, 2, FALSE) -> GA 75 Hose - (1625 5953 00) | D38: =VLOOKUP(B38, 'Full List'!B:G, 6, FALSE) -> 478500 | E38: =VLOOKUP(B38, 'Full List'!B:F, 5, FALSE) -> 1 | F38: =VLOOKUP(B38, 'Full List'!B:H, 7, FALSE) -> 478500 | G38: https://drive.google.com/open?id=1vfeBOOiRKLtROS0AynmGm1Pg-u3SPmON https://drive.google.com/open?id=148QeSsasVO8TscOcbAnCP48jFzV6D8ih https://drive.google.com/open?id=1Bs88qjz7rA5mZaZP6zInHnht0EdnW3N7
A39: 46163.3 | B39: SM.002.000357.14.5P | C39: =VLOOKUP(B39, 'Full List'!B:C, 2, FALSE) -> Valve control 3 way (39497672) | D39: =VLOOKUP(B39, 'Full List'!B:G, 6, FALSE) -> 167580 | E39: =VLOOKUP(B39, 'Full List'!B:F, 5, FALSE) -> 2 | F39: =VLOOKUP(B39, 'Full List'!B:H, 7, FALSE) -> 335160 | G39: https://drive.google.com/open?id=15we1HRuWVdcnbOvYqXassio6FDst8Uyu https://drive.google.com/open?id=1XEApcqS1ZE5mpkHf7mrzuNoh6ZKIvkyN
... A101: 46164.65 | B101: SM.016.006896.03.75 | C101: =VLOOKUP(B101, 'Full List'!B:C, 2, FALSE) -> HOSE (FILTER BAG) 088422.00 | D101: =VLOOKUP(B101, 'Full List'!B:G, 6, FALSE) -> 6624.73 | E101: =VLOOKUP(B101, 'Full List'!B:F, 5, FALSE) -> 549 | F101: =VLOOKUP(B101, 'Full List'!B:H, 7, FALSE) -> 3636976.8 | G101: https://drive.google.com/open?id=1NPBtI8tr6Ql3QduYRicUXSJjuSAv-qe5 https://drive.google.com/open?id=1QP8EGxUEVPYSn5J0e8U0zcifcsmW9QMO
A102: 46167.429 | C102: =VLOOKUP(B102, 'Full List'!B:C, 2, FALSE) -> #N/A | F102: =VLOOKUP(B102, 'Full List'!B:H, 7, FALSE) -> #N/A | G102: https://drive.google.com/open?id=1hkGPbfq4yGNibje3wTv_afkFUJ6eEq39 https://drive.google.com/open?id=1tiKzCHDTS8sh688xVZP-u0H-W0hV4x51

Sheet Full List
B1: Organization: GSC | C1: Description | D1: Primary UOM | E1: Currency | F1: Unit value | G1: Quantity Total | H1: Value Total
B2: SE.001.000039.00.00 | C2: MAGNETIC CONTACTOR-15KW 110V | D2: EA | E2: LKR | F2: 20 | G2: 20037.48 | H2: 400749.6
B3: SE.001.000042.00.00 | C3: MAGNETIC CONTACTOR-18.5KW 110V | D3: EA | E3: LKR | F3: 6 | G3: 35900 | H3: 215400
B4: SE.001.000054.00.00 | C4: MAGNETIC CONTACTOR-22KW 110V | D4: EA | E4: LKR | F4: 15 | G4: 30677.8 | H4: 460167
B5: SE.001.000075.05.84 | C5: MAGNETIC CONTACTOR-7.5KW 110V | D5: EA | E5: LKR | F5: 49 | G5: 8543.35 | H5: 418624.15
B6: SE.001.000139.05.86 | C6: RELAY-PHO20015917/21.2/48 | D6: EA | E6: EUR | F6: 4 | G6: 128620.04 | H6: 514480.16
B7: SE.001.000159.00.00 | C7: RELAY-THERMAL OVERLOAD 32-50A | D7: EA | E7: LKR | F7: 15 | G7: 20453.86 | H7: 306807.9
B8: SE.001.000177.00.00 | C8: THERMAL MAGNETIC SWITCH-0.6-1A | D8: EA | E8: LKR | F8: 12 | G8: 15118.33 | H8: 181419.96
B9: SE.001.000178.00.00 | C9: THERMAL MAGNETIC SWITCH-1-1.6A | D9: EA | F9: 21 | G9: 11093.73 | H9: 232968.33
B10: SE.001.000338.00.00 | C10: CONTACT POINT FOR 3TF52 CONTACTOR | D10: EA | E10: LKR | F10: 18 | G10: 66775 | H10: 1201950
B11: SE.001.000349.00.00 | C11: MAGNATIC CONTACTOR 3RT1036 / 24V AC | D11: EA | E11: LKR | F11: 13 | G11: 26985.66 | H11: 350813.58
B12: SE.001.000410.07.3N | C12: CONTACTOR AF26-30-00-11 24/60V-(SPCTEAB0440) | D12: EA | F12: 20 | G12: 13564.64 | H12: 271292.8
B13: SE.001.000411.07.3N | C13: CONTACTOR AF16-30-01-11 24/60V-(SPCTEAB0407) | D13: EA | F13: 27 | G13: 11997.17 | H13: 323923.59
B14: SE.001.000441.00.00 | C14: MAGNETIC CONTACTOR 3TF5222-0AK6 (2NO, 2NC, 110 VAC) | D14: EA | E14: LKR | F14: 12 | G14: 69135.96 | H14: 829631.52
B15: SE.001.000447.06.1T | C15: STATIC RELAY G 3R.ODX02SN (SPCTEAE0129) | D15: EA | E15: EUR | F15: 23 | G15: 11144.1 | H15: 256314.3
B16: SE.001.000451.07.1T | C16: CONTACTOR AF16-30-10-11 24/60V (SPCTEAB0411) | D16: EA | F16: 30 | G16: 10134.09 | H16: 304022.7
B17: SE.001.000452.07.1T | C17: CONTACTOR AF30-30-00-11 24/60V SPCTEAB0444) | D17: EA | F17: 41 | G17: 18349.67 | H17: 752336.47
B18: SE.001.000462.08.AM | C18: SAFETY RELAYT (7700101009) | D18: EA | E18: EUR | F18: 12 | G18: 19165.94 | H18: 229991.28
B19: SE.001.000485.02.47 | C19: RELAY 4060488 | D19: EA | E19: EUR | F19: 2 | G19: 111235.99 | H19: 222471.98
B20: SE.001.001000.07.1T | C20: ABB AUXILIARY CONTACT BLOCK (NC) | D20: EA | F20: 218 | G20: 1221.83 | H20: 266358.94
B21: SE.001.001001.07.1T | C21: ABB AUXILIARY CONTACT BLOCK (NO) | D21: EA | F21: 236 | G21: 1014.39 | H21: 239396.04
B22: SE.001.001178.00.00 | C22: THERMAL OVERLOAD RELAY 50 - 200A (3RB2056 - 1FC2) | D22: EA | E22: LKR | F22: 3 | G22: 83408.33 | H22: 250224.99
B23: SE.001.003004.05.86 | C23: MAGNETIC CONTACTOR[ 55kW/110VAC/3RT 1054] | D23: EA | E23: LKR | F23: 4 | G23: 81690 | H23: 326760
B24: SE.001.003013.00.01 | C24: MAGNATIC CONTACTOR AF 09.30.10.11 24VAC | D24: EA | F24: 59 | G24: 7545.56 | H24: 445188.04
B25: SE.001.003014.00.01 | C25: MAGNATIC CONTACTOR AF 09.30.01.11 24VAC | D25: EA | F25: 55 | G25: 7953.7 | H25: 437453.5
B26: SE.001.003019.00.00 | C26: MAGNETIC CONTACTOR LC1D115/55KW/110VAC SCHNEIDER | D26: EA | E26: LKR | F26: 3 | G26: 82237.5 | H26: 246712.5
B27: SE.001.003027.00.00 | C27: CAPACITOR CONTACTOR-LOVATO BF3800A | D27: EA | E27: LKR | F27: 6 | G27: 30872 | H27: 185232
B28: SE.002.000045.00.00 | C28: MCCB-400A | D28: EA | E28: LKR | F28: 4 | G28: 69571.5 | H28: 278286
B29: SE.002.000075.00.00 | C29: MCCB-125A 3 POLE 25 KA | D29: EA | E29: LKR | F29: 17 | G29: 20677.38 | H29: 351515.46
B30: SE.002.000127.00.00 | C30: 1600A, 400V, 55-85kA, 4P MCCB WITH UVT COIL | D30: EA | E30: LKR | F30: 1 | G30: 394383.9 | H30: 394383.9
B31: SE.002.000138.00.00 | C31: 1600A, 450V 85/65KA 3POLE MCCB WITH COMPLETE UVT COIL SET | D31: EA | E31: LKR | F31: 1 | G31: 461252 | H31: 461252
B32: SE.003.000111.00.00 | C32: TIMER MTD16086928 (4033600) | D32: EA | E32: EUR | F32: 3 | G32: 173136.97 | H32: 519410.91
B33: SE.003.000113.12.00 | C33: TIMER FOR FAST MILL | D33: EA | F33: 4 | G33: 57066.14 | H33: 228264.56
B34: SE.003.000249.00.00 | C34: TIMER 04033607 | D34: EA | F34: 3 | G34: 60628.8 | H34: 181886.4
B35: SE.003.000771.02.47 | C35: INDICATOR 4319109 | D35: EA | E35: EUR | F35: 1 | G35: 189415.49 | H35: 189415.49
B36: SE.003.000772.02.47 | C36: TIMER 4033614 | D36: EA | F36: 4 | G36: 44536.73 | H36: 178146.92
B37: SE.004.000136.08.AM | C37: INFORMER CARRIAGE BUTTON UNIT (2C002187) | D37: EA | E37: EUR | F37: 1 | G37: 258722.03 | H37: 258722.03
B38: SE.005.000018.07.3K | C38: ENCODER-3880SE0030 | D38: EA | E38: EUR | F38: 4 | G38: 45748.99 | H38: 182995.96
B39: SE.005.000025.05.86 | C39: ENCODER-4460507-18A/21 | D39: EA | E39: EUR | F39: 2 | G39: 273407.24 | H39: 546814.48
B40: SE.005.000032.05.1A | C40: ENCODER-EVA27087914 11A 09 | D40: EA | E40: EUR | F40: 6 | G40: 30883.75 | H40: 185302.5
...
